Workbook

Sheet Feature Specs
A1: Category | B1: Feature | C1: Description | D1: Status | E1: Priority | F1: Notes
A2: Onboarding | B2: Name input | C2: User enters their name | D2: Built | E2: P0
B3: Date of birth | C3: Calculates zodiac and compatibility | D3: Built | E3: P0
B4: Age verification | C4: Under 18 locks mature/romantic content | D4: Built | E4: P0 | F4: Required for app store
B5: Energy/vibe | C5: Multi-select personality energy | D5: Built | E5: P0
B6: Communication style | C6: Multi-select how they communicate | D6: Built | E6: P0
B7: Occupation | C7: Free text work description | D7: Built | E7: P0
B8: Relationship status | C8: Multi-select current situation | D8: Built | E8: P0
B9: Love language | C9: Multi-select love languages | D9: Built | E9: P0
B10: Emotional needs | C10: What they wish they had more of | D10: Built | E10: P0
B11: Social identity | C11: How friends describe them | D11: Built | E11: P0
B12: Activities (15 options) | C12: Multi-select hobbies and interests | D12: Built | E12: P0
B13: Activity subcategories | C13: Drill-down genres/types per activity | D13: Built | E13: P0 | F13: Optional — can tell companions later
B14: Cuisines loved | C14: Multi-select favorite food types | D14: Built | E14: P0
B15: Cuisines disliked | C15: Multi-select foods to avoid | D15: Built | E15: P0 | F15: Companions never suggest these
B16: Dietary restrictions | C16: Multi-select dietary needs | D16: Built | E16: P0
B17: Favorite movies/shows | C17: Free text entertainment preferences | D17: Built | E17: P0
B18: Favorite music artists | C18: Free text music preferences | D18: Built | E18: P0
B19: Back navigation | C19: Go back to change any answer | D19: Built | E19: P0 | F19: Pre-populates previous answers
B20: Multi-select on all steps | C20: Except name and DOB | D20: Built | E20: P0
A21: Zodiac System | B21: Western zodiac | C21: Sun sign from birthdate | D21: Built | E21: P0
B22: Chinese zodiac | C22: Animal + element from birth year | D22: Built | E22: P0
B23: Numerology life path | C23: Life path number calculation | D23: Built | E23: P0
B24: Vedic/sidereal astrology | C24: Moon sign and nakshatra | D24: Future | E24: P1
B25: Compatibility matching | C25: Companions get compatible signs | D25: Built | E25: P0
B26: Zodiac reveal screen | C26: Animated profile presentation | D26: Built | E26: P0
A27: Companion Gen | B27: Surprise Me path | C27: Pure zodiac-based generation | D27: Built | E27: P0
B28: Guide Me builder | C28: Grouped multi-select trait seeds | D28: Built | E28: P0 | F28: 2 screens: personality + relationship
B29: Optional free text | C29: Additional vibe description on both paths | D29: Built | E29: P0
B30: Waking up sequence | C30: Companions discover themselves live | D30: Built | E30: P0 | F30: Name, pronouns, zodiac, personality
B31: Self-naming | C31: Companions choose their own names | D31: Built | E31: P0 | F31: Based on zodiac element pools
B32: Self-pronouns | C32: Companions choose he/she/they | D32: Built | E32: P0
B33: Color identity | C33: Each companion has a distinct color | D33: Built | E33: P0 | F33: Violet, Rose, Teal
B34: Companion selection | C34: Choose 1 (free) or all 3 (trial) | D34: Built | E34: P0
B35: "Older" presentation | C35: Companions can present as older for 18+ | D35: Future | E35: P1 | F35: Autonomous based on onboarding data
A36: Builder Traits | B36: Demeanor | C36: Warm, Edgy, Calm, Chaotic, Mysterious, Playful | D36: Built | E36: P0 | F36: Multi-select
B37: Energy | C37: Laid back, High energy, Balanced | D37: Built | E37: P0
B38: Humor | C38: Light, Dark, Dry, Goofy, Sarcastic, Witty | D38: Built | E38: P0
B39: Emotional depth | C39: Light & fun, Emotionally open, Deeply intense | D39: Built | E39: P0
B40: Social energy | C40: Introverted, Selectively social, Life of party | D40: Built | E40: P0
...

Sheet Summary
A1: OTHER App — Spec Summary
A3: Total Features | B3: =COUNTA('Feature Specs'!B2:B115) -> 114
A4: Built | B4: =COUNTIF('Feature Specs'!D2:D115,"Built") -> 64
A5: Partial | B5: =COUNTIF('Feature Specs'!D2:D115,"Partial") -> 9
A6: Future | B6: =COUNTIF('Feature Specs'!D2:D115,"Future") -> 41
A8: P0 (Critical) | B8: =COUNTIF('Feature Specs'!E2:E115,"P0") -> 76
A9: P1 (Important) | B9: =COUNTIF('Feature Specs'!E2:E115,"P1") -> 29
A10: P2 (Nice to have) | B10: =COUNTIF('Feature Specs'!E2:E115,"P2") -> 9
A12: Categories
A13: Onboarding | B13: =COUNTIF('Feature Specs'!A2:A115,"Onboarding") -> 1
A14: Zodiac System | B14: =COUNTIF('Feature Specs'!A2:A115,"Zodiac System") -> 1
A15: Companion Gen | B15: =COUNTIF('Feature Specs'!A2:A115,"Companion Gen") -> 1
A16: Builder Traits | B16: =COUNTIF('Feature Specs'!A2:A115,"Builder Traits") -> 1
A17: Chat System | B17: =COUNTIF('Feature Specs'!A2:A115,"Chat System") -> 1
A18: Companion Dynamics | B18: =COUNTIF('Feature Specs'!A2:A115,"Companion Dynamics") -> 1
A19: Emotional Intel | B19: =COUNTIF('Feature Specs'!A2:A115,"Emotional Intel") -> 1
A20: Location | B20: =COUNTIF('Feature Specs'!A2:A115,"Location") -> 1
A21: Content/Age | B21: =COUNTIF('Feature Specs'!A2:A115,"Content/Age") -> 1
A22: Monetization | B22: =COUNTIF('Feature Specs'!A2:A115,"Monetization") -> 1
A23: Data/Privacy | B23: =COUNTIF('Feature Specs'!A2:A115,"Data/Privacy") -> 1
A24: Visual/UI | B24: =COUNTIF('Feature Specs'!A2:A115,"Visual/UI") -> 1
A25: Notifications | B25: =COUNTIF('Feature Specs'!A2:A115,"Notifications") -> 1
A26: Platforms | B26: =COUNTIF('Feature Specs'!A2:A115,"Platforms") -> 1
A27: Backend | B27: =COUNTIF('Feature Specs'!A2:A115,"Backend") -> 1
